Traceback (most recent call last):
  File "/usr/local/lib/python3.7/dist-packages/jupyter_cache/executors/utils.py", line 56, in single_nb_execution
    record_timing=False,
  File "/usr/local/lib/python3.7/dist-packages/nbclient/client.py", line 1204, in execute
    return NotebookClient(nb=nb, resources=resources, km=km, **kwargs).execute()
  File "/usr/local/lib/python3.7/dist-packages/nbclient/util.py", line 84, in wrapped
    return just_run(coro(*args, **kwargs))
  File "/usr/local/lib/python3.7/dist-packages/nbclient/util.py", line 62, in just_run
    return loop.run_until_complete(coro)
  File "/usr/lib/python3.7/asyncio/base_events.py", line 587, in run_until_complete
    return future.result()
  File "/usr/local/lib/python3.7/dist-packages/nbclient/client.py", line 664, in async_execute
    cell, index, execution_count=self.code_cells_executed + 1
  File "/usr/local/lib/python3.7/dist-packages/nbclient/client.py", line 965, in async_execute_cell
    await self._check_raise_for_error(cell, cell_index, exec_reply)
  File "/usr/local/lib/python3.7/dist-packages/nbclient/client.py", line 862, in _check_raise_for_error
    raise CellExecutionError.from_cell_and_msg(cell, exec_reply_content)
nbclient.exceptions.CellExecutionError: An error occurred while executing the following cell:
------------------
from google.colab import drive
drive.mount('/content/drive/My Drive/')
------------------

[0;31m[0m
[0;31mValueError[0mTraceback (most recent call last)
[0;32m<ipython-input-174-7efe620a4c10>[0m in [0;36m<module>[0;34m[0m
[1;32m      1[0m [0;32mfrom[0m [0mgoogle[0m[0;34m.[0m[0mcolab[0m [0;32mimport[0m [0mdrive[0m[0;34m[0m[0;34m[0m[0m
[0;32m----> 2[0;31m [0mdrive[0m[0;34m.[0m[0mmount[0m[0;34m([0m[0;34m'/content/drive/My Drive/'[0m[0;34m)[0m[0;34m[0m[0;34m[0m[0m
[0m
[0;32m/usr/local/lib/python3.7/dist-packages/google/colab/drive.py[0m in [0;36mmount[0;34m(mountpoint, force_remount, timeout_ms, readonly)[0m
[1;32m    104[0m       [0mtimeout_ms[0m[0;34m=[0m[0mtimeout_ms[0m[0;34m,[0m[0;34m[0m[0;34m[0m[0m
[1;32m    105[0m       [0mephemeral[0m[0;34m=[0m[0;32mTrue[0m[0;34m,[0m[0;34m[0m[0;34m[0m[0m
[0;32m--> 106[0;31m       readonly=readonly)
[0m[1;32m    107[0m [0;34m[0m[0m
[1;32m    108[0m [0;34m[0m[0m

[0;32m/usr/local/lib/python3.7/dist-packages/google/colab/drive.py[0m in [0;36m_mount[0;34m(mountpoint, force_remount, timeout_ms, ephemeral, readonly)[0m
[1;32m    117[0m [0;34m[0m[0m
[1;32m    118[0m   [0;32mif[0m [0;34m' '[0m [0;32min[0m [0mmountpoint[0m[0;34m:[0m[0;34m[0m[0;34m[0m[0m
[0;32m--> 119[0;31m     [0;32mraise[0m [0mValueError[0m[0;34m([0m[0;34m'Mountpoint must not contain a space.'[0m[0;34m)[0m[0;34m[0m[0;34m[0m[0m
[0m[1;32m    120[0m [0;34m[0m[0m
[1;32m    121[0m   metadata_server_addr = _os.environ[

[0;31mValueError[0m: Mountpoint must not contain a space.
ValueError: Mountpoint must not contain a space.

